Traceback (most recent call last):
  File "/Users/icaru/miniconda3/envs/ACEBook/lib/python3.9/site-packages/jupyter_cache/executors/utils.py", line 51, in single_nb_execution
    executenb(
  File "/Users/icaru/miniconda3/envs/ACEBook/lib/python3.9/site-packages/nbclient/client.py", line 1204, in execute
    return NotebookClient(nb=nb, resources=resources, km=km, **kwargs).execute()
  File "/Users/icaru/miniconda3/envs/ACEBook/lib/python3.9/site-packages/nbclient/util.py", line 84, in wrapped
    return just_run(coro(*args, **kwargs))
  File "/Users/icaru/miniconda3/envs/ACEBook/lib/python3.9/site-packages/nbclient/util.py", line 62, in just_run
    return loop.run_until_complete(coro)
  File "/Users/icaru/miniconda3/envs/ACEBook/lib/python3.9/asyncio/base_events.py", line 647, in run_until_complete
    return future.result()
  File "/Users/icaru/miniconda3/envs/ACEBook/lib/python3.9/site-packages/nbclient/client.py", line 663, in async_execute
    await self.async_execute_cell(
  File "/Users/icaru/miniconda3/envs/ACEBook/lib/python3.9/site-packages/nbclient/client.py", line 965, in async_execute_cell
    await self._check_raise_for_error(cell, cell_index, exec_reply)
  File "/Users/icaru/miniconda3/envs/ACEBook/lib/python3.9/site-packages/nbclient/client.py", line 862, in _check_raise_for_error
    raise CellExecutionError.from_cell_and_msg(cell, exec_reply_content)
nbclient.exceptions.CellExecutionError: An error occurred while executing the following cell:
------------------
ELP_08 = read.csv("./Data/ELP_08_caffeine_side_learning_Y_maze.csv", header = TRUE, stringsAsFactors = FALSE, sep = ";")
head(ELP_08, n = 1) # Check if data was imported correctly
------------------

Error in file(file, "rt"): cannot open the connection
Traceback:

1. read.csv("./Data/ELP_08_caffeine_side_learning_Y_maze.csv", header = TRUE, 
 .     stringsAsFactors = FALSE, sep = ";")
2. read.table(file = file, header = header, sep = sep, quote = quote, 
 .     dec = dec, fill = fill, comment.char = comment.char, ...)
3. file(file, "rt")
ERROR: Error in file(file, "rt"): cannot open the connection


